<?xml version="1.0" encoding="utf-8"?>
<robot name="rex_full">
  <material name="yellow">
    <color rgba="0.92 0.83 0.0 1"/>
  </material>
  <material name="black">
    <color rgba="0.1 0.1 0.1 1"/>
  </material>
  <material name="grey">
    <color rgba="0.6 0.6 0.6 1"/>
  </material>
  <material name="dark_grey">
    <color rgba="149 165 166 1"/>  
  </material>
  <material name="orange">
    <color rgba="0.98 0.35 0.0 1"/>
  </material>
  <!-- Params -->
  <!-- Macros -->
  <!-- Robot Body -->
  <link name="base_link">
    <visual>
      <geometry>
        <mesh filename="stl/mainbody.stl" scale="0.001 0.001 0.001"/>
      </geometry>
      <material name="black"/>
      <origin rpy="0 0 0" xyz="-0.045 -0.060 -0.015"/>
    </visual>
    <collision>
      <geometry>
        <box size="0.14 0.11 0.07"/>
      </geometry>
      <origin rpy="0 0 0" xyz="0 0 0"/>
    </collision>
    <inertial>
      <mass value="1.20"/>
      <inertia ixx="100" ixy="0" ixz="0" iyy="100" iyz="0" izz="100"/>
    </inertial>
  </link>

 <!-- Lidar Backpack 
  <link name="lidar_link">
   <visual>
     <geometry>
       <mesh filename="stl/rplidar_main.stl" scale="0.001 0.001 0.001"/>
     </geometry>
     <material name="black"/>
     <origin rpy="1.57075 0 0" xyz="-0.06425 0.02885 0"/>
   </visual>
   <collision>
     <geometry>
       <box size="0.0985 0.0577 0.07"/>
     </geometry>
     <origin rpy="0 0 0" xyz="0 0 0"/>
   </collision>
   <inertial>
     <mass value="0.1"/>
     <inertia ixx="100" ixy="0" ixz="0" iyy="100" iyz="0" izz="100"/>
   </inertial>
  </link>
  <joint name="base_lidar" type="fixed">
   <parent link="base_link"/>
   <child link="lidar_link"/>
   <origin xyz="0 0 0.035"/>
  </joint> -->

  <!-- create head & tail -->
  <link name="chassis_front_link">
    <visual>
      <geometry>
        <mesh filename="stl/frontpart.stl" scale="0.001 0.001 0.001"/>
      </geometry>
      <origin rpy="0 0 0" xyz="-0.040 -0.060 -0.0140"/>
      <material name="yellow"/>
    </visual>
    <collision>
      <geometry>
        <box size="0.058 0.11 0.07"/>
      </geometry>
      <origin rpy="0 0 0" xyz="-0.145 0 0"/>
    </collision>
    <inertial>
      <mass value="0.05"/>
      <inertia ixx="100" ixy="0" ixz="0" iyy="100" iyz="0" izz="100"/>
    </inertial>
  </link>
  <joint name="chassis_base_front" type="fixed">
    <parent link="base_link"/>
    <child link="chassis_front_link"/>
  </joint>
  <link name="chassis_rear_link">
    <visual>
      <geometry>
        <mesh filename="stl/backpart.stl" scale="0.001 0.001 0.001"/>
      </geometry>
      <origin rpy="0 0 0" xyz="0.05 -0.005 -0.042"/>
      <material name="yellow"/>
    </visual>
    <collision>
      <geometry>
        <box size="0.04 0.11 0.07"/>
      </geometry>
      <origin rpy="0 0 0" xyz="0.135 0 0"/>
    </collision>
    <inertial>
      <mass value="0.05"/>
      <inertia ixx="100" ixy="0" ixz="0" iyy="100" iyz="0" izz="100"/>
    </inertial>
  </link>
  <joint name="chassis_base_rear" type="fixed">
    <parent link="base_link"/>
    <child link="chassis_rear_link"/>
  </joint>

  <!-- Front Left Leg -->
  <link name="front_left_shoulder_link">
    <visual>
      <geometry>
        <mesh filename="stl/lshoulder.stl" scale="0.001 0.001 0.001"/>
      </geometry>
      <origin rpy="0 0 0" xyz="-0.135 -0.02 -0.01"/>
      <material name="black"/>
    </visual>
    <collision>
      <geometry>
        <box size="0.044 0.038 0.07"/>
      </geometry>
      <origin rpy="0 0 0" xyz="0 0 0"/>
    </collision>
    <inertial>
      <mass value="0.10"/>
      <inertia ixx="100" ixy="0" ixz="0" iyy="100" iyz="0" izz="100"/>
    </inertial>
  </link>
  <link name="front_left_leg_link_cover">
    <visual>
      <geometry>
        <mesh filename="stl/upper_leg_shell_cover.stl" scale="0.001 0.001 0.001"/>
      </geometry>
      <origin rpy="0 0 -1.5" xyz="0.002 0.0 -0.16"/>
      <material name="yellow"/>
    </visual>
    <inertial>
      <mass value="0.5"/>
      <inertia ixx="100" ixy="0" ixz="0" iyy="100" iyz="0" izz="100"/>
    </inertial>
  </link>
  <link name="front_left_leg_link">
    <visual>
      <geometry>
        <mesh filename="stl/upper_leg_shell_base.stl" scale="0.001 0.001 0.001"/>
      </geometry>
      <origin rpy="0 0 -1.5" xyz="0.002 0.0 -0.16"/>
      <material name="black"/>
    </visual>
    <collision>
      <origin rpy="0.0 0.0 0.0" xyz="0.0 0.0 -0.05"/>
      <geometry>
        <box size="0.028 0.036 0.12"/>
      </geometry>
    </collision>
    <inertial>
      <mass value="0.1"/>
      <inertia ixx="100" ixy="0" ixz="0" iyy="100" iyz="0" izz="100"/>
    </inertial>
  </link>
  <link name="front_left_foot_link">
    <visual>
      <geometry>
        <mesh filename="stl/lower_leg_solid.stl" scale="0.001 0.001 0.001"/>
      </geometry>
      <origin rpy="0 0 1.5" xyz="0.0 0.0 0.0"/>
      <material name="black"/>
    </visual>
    <collision>
      <geometry>
        <box size="0.026 0.020 0.115"/>
      </geometry>
      <origin rpy="0.0 0.0 0.0" xyz="0.0 0.0 -0.050"/>
    </collision>
    <inertial>
      <mass value="0.1"/>
      <inertia ixx="100" ixy="0" ixz="0" iyy="100" iyz="0" izz="100"/>
    </inertial>
  </link>
  <link name="front_left_toe_link">
    <visual>
      <geometry>
        <mesh filename="stl/foot.stl" scale="0.001 0.001 0.001"/>
      </geometry>
      <origin rpy="0 0 0" xyz="0.0 -0.01 -0.045"/>
      <material name="grey"/>
    </visual>
    <collision>
      <geometry>
        <mesh filename="stl/foot.stl" scale="0.001 0.001 0.001"/>
      </geometry>
      <origin rpy="0 0 0" xyz="0 -0.01 -0.045"/>
      <contact_coefficients mu="100.0"/>
    </collision>
    <inertial>
      <mass value="0.005"/>
      <inertia ixx="100" ixy="0" ixz="0" iyy="100" iyz="0" izz="100"/>
    </inertial>
  </link>
  <joint name="motor_shoulder_FL" type="revolute">
    <parent link="base_link"/>
    <child link="front_left_shoulder_link"/>
    <axis xyz="1 0 0"/>
    <origin rpy="0 0 0" xyz="-0.093 -0.036 0"/>
    <limit effort="100.0" lower="-1.0" upper="1.0" velocity="0.7"/>
    <dynamics damping="0.0" friction="0.5"/>
  </joint>
  <joint name="motor_leg_FL" type="revolute">
    <parent link="front_left_shoulder_link"/>
    <child link="front_left_leg_link"/>
    <axis xyz="0 1 0"/>
    <origin rpy="0 0 0" xyz="0 -0.052 0"/>
    <limit effort="100.0" lower="-1.57" upper="1.57" velocity="0.5"/>
    <dynamics damping="0.0" friction="0.0"/>
  </joint>
  <joint name="front_left_leg_cover_joint" type="fixed">
    <parent link="front_left_leg_link"/>
    <child link="front_left_leg_link_cover"/>
    <origin xyz="0 0 0"/>
  </joint>
  <joint name="foot_motor_FL" type="revolute">
    <parent link="front_left_leg_link"/>
    <child link="front_left_foot_link"/>
    <axis xyz="0 1 0"/>
    <origin rpy="0 0 0" xyz="0.002 -0.02 -0.16"/>
    <limit effort="100.0" lower="-3.14" upper="3.14" velocity="0.5"/>
    <dynamics damping="0.0" friction="0.5"/>
  </joint>
  <joint name="front_left_toe" type="fixed">
    <parent link="front_left_foot_link"/>
    <child link="front_left_toe_link"/>
    <origin xyz="0 0 -0.115"/>
  </joint>

  <!-- Front Right Leg -->
  <link name="front_right_shoulder_link">
    <visual>
      <geometry>
        <mesh filename="stl/rshoulder.stl" scale="0.001 0.001 0.001"/>
      </geometry>
      <origin rpy="0 0 0" xyz="-0.135 -0.102 -0.01"/>
      <material name="black"/>
    </visual>
    <collision>
      <geometry>
        <box size="0.044 0.038 0.07"/>
      </geometry>
      <origin rpy="0 0 0" xyz="0 0 0"/>
    </collision>
    <inertial>
      <mass value="0.10"/>
      <inertia ixx="100" ixy="0" ixz="0" iyy="100" iyz="0" izz="100"/>
    </inertial>
  </link>
  <link name="front_right_leg_link_cover">
    <visual>
      <geometry>
        <mesh filename="stl/upper_leg_shell_cover.stl" scale="0.001 0.001 0.001"/>
      </geometry>
      <origin rpy="0 0 1.5" xyz="0.002 0.0 -0.16"/>
      <material name="yellow"/>
    </visual>
    <inertial>
      <mass value="0.5"/>
      <inertia ixx="100" ixy="0" ixz="0" iyy="100" iyz="0" izz="100"/>
    </inertial>
  </link>
  <link name="front_right_leg_link">
    <visual>
      <geometry>
        <mesh filename="stl/upper_leg_shell_base.stl" scale="0.001 0.001 0.001"/>
      </geometry>
      <origin rpy="0 0 1.5" xyz="0.002 0.0 -0.16"/>
      <material name="black"/>
    </visual>
    <collision>
      <origin rpy="0.0 0.0 0.0" xyz="0.0 0.0 -0.050"/>
      <geometry>
        <box size="0.028 0.036 0.12"/>
      </geometry>
    </collision>
    <inertial>
      <mass value="0.1"/>
      <inertia ixx="100" ixy="0" ixz="0" iyy="100" iyz="0" izz="100"/>
    </inertial>
  </link>
  <link name="front_right_foot_link">
    <visual>
      <geometry>
        <mesh filename="stl/lower_leg_solid.stl" scale="0.001 0.001 0.001"/>
      </geometry>
      <origin rpy="0 0 -1.5" xyz="0 0 0"/>
      <material name="black"/>
    </visual>
    <collision>
      <geometry>
        <box size="0.026 0.020 0.115"/>
      </geometry>
      <origin rpy="0.0 0.0 0.0" xyz="0.0 0.0 -0.050"/>
    </collision>
    <inertial>
      <mass value="0.1"/>
      <inertia ixx="100" ixy="0" ixz="0" iyy="100" iyz="0" izz="100"/>
    </inertial>
  </link>
  <link name="front_right_toe_link">
    <visual>
      <geometry>
        <mesh filename="stl/foot.stl" scale="0.001 0.001 0.001"/>
      </geometry>
      <origin rpy="0 0 0" xyz="0.0 -0.01 -0.045"/>
      <material name="grey"/>
    </visual>
    <collision>
      <geometry>
        <mesh filename="stl/foot.stl" scale="0.001 0.001 0.001"/>
      </geometry>
      <origin rpy="0 0 0" xyz="0.0 -0.01 -0.045"/>
      <contact_coefficients mu="100.0"/>
    </collision>
    <inertial>
      <mass value="0.005"/>
      <inertia ixx="100" ixy="0" ixz="0" iyy="100" iyz="0" izz="100"/>
    </inertial>
  </link>
  <joint name="motor_shoulder_FR" type="revolute">
    <parent link="base_link"/>
    <child link="front_right_shoulder_link"/>
    <axis xyz="1 0 0"/>
    <origin rpy="0 0 0" xyz="-0.093 0.036 0"/>
    <limit effort="100.0" lower="-1.0" upper="1.0" velocity="0.7"/>
    <dynamics damping="0.0" friction="0.5"/>
  </joint>
  <joint name="motor_leg_FR" type="revolute">
    <parent link="front_right_shoulder_link"/>
    <child link="front_right_leg_link"/>
    <axis xyz="0 1 0"/>
    <origin rpy="0 0 0" xyz="0 0.042 0"/>
    <limit effort="100.0" lower="-1.57" upper="1.57" velocity="0.5"/>
    <dynamics damping="0.0" friction="0.0"/>
  </joint>
  <joint name="front_right_leg_cover_joint" type="fixed">
    <parent link="front_right_leg_link"/>
    <child link="front_right_leg_link_cover"/>
    <origin xyz="0 0 0"/>
  </joint>
  <joint name="foot_motor_FR" type="revolute">
    <parent link="front_right_leg_link"/>
    <child link="front_right_foot_link"/>
    <axis xyz="0 1 0"/>
    <origin rpy="0 0 0" xyz="0.002 0.02 -0.16"/>
    <limit effort="100.0" lower="-3.14" upper="3.14" velocity="0.5"/>
    <dynamics damping="0.0" friction="0.5"/>
  </joint>
  <joint name="front_right_toe" type="fixed">
    <parent link="front_right_foot_link"/>
    <child link="front_right_toe_link"/>
    <origin xyz="0 0 -0.115"/>
  </joint>

  <!-- Rear Left Leg -->
  <link name="rear_left_shoulder_link">
    <visual>
      <geometry>
        <mesh filename="stl/lshoulder.stl" scale="0.001 0.001 0.001"/>
      </geometry>
      <origin rpy="0 0 0" xyz="-0.135 -0.02 -0.01"/>
      <material name="black"/>
    </visual>
    <collision>
      <geometry>
        <box size="0.044 0.038 0.07"/>
      </geometry>
      <origin rpy="0 0 0" xyz="0 0 0"/>
    </collision>
    <inertial>
      <mass value="0.10"/>
      <inertia ixx="100" ixy="0" ixz="0" iyy="100" iyz="0" izz="100"/>
    </inertial>
  </link>
  <link name="rear_left_leg_link_cover">
    <visual>
      <geometry>
        <mesh filename="stl/upper_leg_shell_cover.stl" scale="0.001 0.001 0.001"/>
      </geometry>
      <origin rpy="0 0 -1.5" xyz="0.002 0.0 -0.16"/>
      <material name="yellow"/>
    </visual>
    <inertial>
      <mass value="0.5"/>
      <inertia ixx="100" ixy="0" ixz="0" iyy="100" iyz="0" izz="100"/>
    </inertial>
  </link>
  <link name="rear_left_leg_link">
    <visual>
      <geometry>
        <mesh filename="stl/upper_leg_shell_base.stl" scale="0.001 0.001 0.001"/>
      </geometry>
      <origin rpy="0 0 -1.5" xyz="0.002 0.0 -0.16"/>
      <material name="black"/>
    </visual>
    <collision>
      <origin rpy="0.0 0.0 0.0" xyz="0.0 0.0 -0.050"/>
      <geometry>
        <box size="0.028 0.036 0.12"/>
      </geometry>
    </collision>
    <inertial>
      <mass value="0.10"/>
      <inertia ixx="100" ixy="0" ixz="0" iyy="100" iyz="0" izz="100"/>
    </inertial>
  </link>
  <link name="rear_left_foot_link">
    <visual>
      <geometry>
        <mesh filename="stl/lower_leg_solid.stl" scale="0.001 0.001 0.001"/>
      </geometry>
      <origin rpy="0 0 1.5" xyz="0 0 0"/>
      <material name="black"/>
    </visual>
    <collision>
      <geometry>
        <box size="0.026 0.020 0.115"/>
      </geometry>
      <origin rpy="0 0 0" xyz="0.0 0.0 -0.050"/>
    </collision>
    <inertial>
      <mass value="0.1"/>
      <inertia ixx="100" ixy="0" ixz="0" iyy="100" iyz="0" izz="100"/>
    </inertial>
  </link>
  <link name="rear_left_toe_link">
    <visual>
      <geometry>
        <mesh filename="stl/foot.stl" scale="0.001 0.001 0.001"/>
      </geometry>
      <origin rpy="0 0 0" xyz="0 -0.01 -0.045"/>
      <material name="grey"/>
    </visual>
    <collision>
      <geometry>
        <mesh filename="stl/foot.stl" scale="0.001 0.001 0.001"/>
      </geometry>
      <origin rpy="0 0 0" xyz="0 -0.01 -0.045"/>
      <contact_coefficients mu="100.0"/>
    </collision>
    <inertial>
      <mass value="0.005"/>
      <inertia ixx="100" ixy="0" ixz="0" iyy="100" iyz="0" izz="100"/>
    </inertial>
  </link>
  <joint name="motor_shoulder_RL" type="revolute">
    <parent link="base_link"/>
    <child link="rear_left_shoulder_link"/>
    <axis xyz="1 0 0"/>
    <origin rpy="0 0 0" xyz="0.093 -0.036 0"/>
    <limit effort="100.0" lower="-1.0" upper="1.0" velocity="0.7"/>
    <dynamics damping="0.0" friction="0.5"/>
  </joint>
  <joint name="motor_leg_RL" type="revolute">
    <parent link="rear_left_shoulder_link"/>
    <child link="rear_left_leg_link"/>
    <axis xyz="0 1 0"/>
    <origin rpy="0 0 0" xyz="0 -0.052 0"/>
    <limit effort="100.0" lower="-1.57" upper="1.57" velocity="0.5"/>
    <dynamics damping="0.0" friction="0.0"/>
  </joint>
  <joint name="rear_left_leg_cover_joint" type="fixed">
    <parent link="rear_left_leg_link"/>
    <child link="rear_left_leg_link_cover"/>
    <origin xyz="0 0 0"/>
  </joint>
  <joint name="foot_motor_RL" type="revolute">
    <parent link="rear_left_leg_link"/>
    <child link="rear_left_foot_link"/>
    <axis xyz="0 1 0"/>
    <origin rpy="0 0 0" xyz="0.002 -0.02 -0.16"/>
    <limit effort="100.0" lower="-3.14" upper="3.14" velocity="0.5"/>
    <dynamics damping="0.0" friction="0.5"/>
  </joint>
  <joint name="rear_left_toe" type="fixed">
    <parent link="rear_left_foot_link"/>
    <child link="rear_left_toe_link"/>
    <origin xyz="0 0 -0.115"/>
  </joint>

  <!-- Rear Right Leg -->
  <link name="rear_right_shoulder_link">
    <visual>
      <geometry>
        <mesh filename="stl/rshoulder.stl" scale="0.001 0.001 0.001"/>
      </geometry>
      <origin rpy="0 0 0" xyz="-0.135 -0.102 -0.01"/>
      <material name="black"/>
    </visual>
    <collision>
      <geometry>
        <box size="0.044 0.038 0.07"/>
      </geometry>
      <origin rpy="0 0 0" xyz="0 0 0"/>
    </collision>
    <inertial>
      <mass value="0.10"/>
      <inertia ixx="100" ixy="0" ixz="0" iyy="100" iyz="0" izz="100"/>
    </inertial>
  </link>
  <link name="rear_right_leg_link_cover">
    <visual>
      <geometry>
        <mesh filename="stl/upper_leg_shell_cover.stl" scale="0.001 0.001 0.001"/>
      </geometry>
      <origin rpy="0 0 1.5" xyz="0.002 0.0 -0.16"/>
      <material name="yellow"/>
    </visual>
    <inertial>
      <mass value="0.5"/>
      <inertia ixx="100" ixy="0" ixz="0" iyy="100" iyz="0" izz="100"/>
    </inertial>
  </link>
  <link name="rear_right_leg_link">
    <visual>
      <geometry>
        <mesh filename="stl/upper_leg_shell_base.stl" scale="0.001 0.001 0.001"/>
      </geometry>
      <origin rpy="0 0 1.5" xyz="0.002 0.0 -0.16"/>
      <material name="black"/>
    </visual>
    <collision>
      <origin rpy="0.0 0.0 0.0" xyz="0.0 0.0 -0.050"/>
      <geometry>
        <box size="0.028 0.036 0.12"/>
      </geometry>
    </collision>
    <inertial>
      <mass value="0.10"/>
      <inertia ixx="100" ixy="0" ixz="0" iyy="100" iyz="0" izz="100"/>
    </inertial>
  </link>
  <link name="rear_right_foot_link">
    <visual>
      <geometry>
        <mesh filename="stl/lower_leg_solid.stl" scale="0.001 0.001 0.001"/>
      </geometry>
      <origin rpy="0 0 -1.5" xyz="0 0 0"/>
      <material name="black"/>
    </visual>
    <collision>
      <geometry>
        <box size="0.026 0.020 0.115"/>
      </geometry>
      <origin rpy="0.0 0.0 0.0" xyz="0.0 0.0 -0.050"/>
    </collision>
    <inertial>
      <mass value="0.1"/>
      <inertia ixx="100" ixy="0" ixz="0" iyy="100" iyz="0" izz="100"/>
    </inertial>
  </link>
  <link name="rear_right_toe_link">
    <visual>
      <geometry>
        <mesh filename="stl/foot.stl" scale="0.001 0.001 0.001"/>
      </geometry>
      <origin rpy="0 0 0" xyz="0.0 -0.01 -0.045"/>
      <material name="grey"/>
    </visual>
    <collision>
      <geometry>
        <mesh filename="stl/foot.stl" scale="0.001 0.001 0.001"/>
      </geometry>
      <origin rpy="0 0 0" xyz="0.0 -0.01 -0.045"/>
      <contact_coefficients mu="100.0"/>
    </collision>
    <inertial>
      <mass value="0.005"/>
      <inertia ixx="100" ixy="0" ixz="0" iyy="100" iyz="0" izz="100"/>
    </inertial>
  </link>
  <joint name="motor_shoulder_RR" type="revolute">
    <parent link="base_link"/>
    <child link="rear_right_shoulder_link"/>
    <axis xyz="1 0 0"/>
    <origin rpy="0 0 0" xyz="0.093 0.036 0"/>
    <limit effort="100.0" lower="-1.0" upper="1.0" velocity="0.7"/>
    <dynamics damping="0.0" friction="0.5"/>
  </joint>
  <joint name="motor_leg_RR" type="revolute">
    <parent link="rear_right_shoulder_link"/>
    <child link="rear_right_leg_link"/>
    <axis xyz="0 1 0"/>
    <origin rpy="0 0 0" xyz="0 0.042 0"/>
    <limit effort="100.0" lower="-1.57" upper="1.57" velocity="0.5"/>
    <dynamics damping="0.0" friction="0.0"/>
  </joint>
  <joint name="rear_right_leg_cover_joint" type="fixed">
    <parent link="rear_right_leg_link"/>
    <child link="rear_right_leg_link_cover"/>
    <origin xyz="0 0 0"/>
  </joint>
  <joint name="foot_motor_RR" type="revolute">
    <parent link="rear_right_leg_link"/>
    <child link="rear_right_foot_link"/>
    <axis xyz="0 1 0"/>
    <origin rpy="0 0 0" xyz="0.002 0.02 -0.16"/>
    <limit effort="100.0" lower="-3.14" upper="3.14" velocity="0.5"/>
    <dynamics damping="0.0" friction="0.5"/>
  </joint>
  <joint name="rear_right_toe" type="fixed">
    <parent link="rear_right_foot_link"/>
    <child link="rear_right_toe_link"/>
    <origin xyz="0 0 -0.115"/>
  </joint>

  <!-- Arm -->
  <link name="arm_long_U">
    <visual>
      <geometry>
        <mesh filename="meshes/long_U.obj"/>
      </geometry>
      <origin rpy="0 0 0" xyz="0 0 0"/>
      <material name="black"/>
    </visual>
    <collision>
      <origin rpy="0 0 0" xyz="0 0 0.01"/>
      <geometry>
        <cylinder length="0.02" radius="0.02"/>
      </geometry>
    </collision>
    <inertial>
      <mass value="1."/>
      <inertia ixx="0.03" ixy="0" ixz="0" iyy="0.03" iyz="0" izz="0.03"/>
    </inertial>
  </link>
  <joint name="motor_arm_m1" type="revolute">
    <origin rpy="0 0 0" xyz="-0.05 -0.005 0.0327993216120967"/>
    <limit effort="100.0" lower="-4.71" upper="1.57" velocity="0.5"/>
    <parent link="base_link"/>
    <child link="arm_long_U"/>
    <axis xyz="0 0 1"/>
  </joint>
  <link name="arm_section_1">
    <visual>
      <origin rpy="0 1.5707963267949 0" xyz="0 0 0"/>
      <geometry>
        <mesh filename="meshes/section_1.obj"/>
      </geometry>
      <material name="black"/>
    </visual>
    <collision>
      <origin rpy="0 1.5707963267949 0" xyz="0.025 0 0"/>
      <geometry>
        <cylinder length="0.05" radius="0.02"/>
      </geometry>
    </collision>
    <inertial>
      <mass value="0.2"/>
      <inertia ixx="0.03" ixy="0" ixz="0" iyy="0.03" iyz="0" izz="0.03"/>
    </inertial>
  </link>
  <joint name="motor_arm_m2" type="revolute">
    <origin rpy="0 -1.5707963267949 0" xyz="0 0 0.0240006783879033"/>
    <parent link="arm_long_U"/>
    <child link="arm_section_1"/>
    <limit effort="100.0" lower="-1.57" upper="1.57" velocity="0.5"/>
    <axis xyz="0 0 -1"/>
  </joint>
  <link name="arm_section_1_ext">
    <visual>
      <origin rpy="0 1.5707963267949 0" xyz="0.05 0 0"/>
      <geometry>
        <mesh filename="meshes/section_1.obj"/>
      </geometry>
      <material name="black"/>
    </visual>
    <collision>
      <origin rpy="0 1.5707963267949 0" xyz="0.025 0 0"/>
      <geometry>
        <cylinder length="0.05" radius="0.02"/>
      </geometry>
    </collision>
    <inertial>
      <mass value="0.2"/>
      <inertia ixx="0.03" ixy="0" ixz="0" iyy="0.03" iyz="0" izz="0.03"/>
    </inertial>
  </link>
  <joint name="arm_1_ext" type="fixed">
    <origin rpy="0 0 0" xyz="0 0 0"/>
    <parent link="arm_section_1"/>
    <child link="arm_section_1_ext"/>
    <axis xyz="0 0 -1"/>
  </joint>
  <link name="arm_section_2">
    <visual>
      <origin rpy="0 1.5707963267949 0" xyz="0 0 0"/>
      <geometry>
        <mesh filename="meshes/section_2.obj"/>
      </geometry>
      <material name="black"/>
    </visual>
    <collision>
      <origin rpy="0 1.5707963267949 0" xyz="0.025 0 0"/>
      <geometry>
        <cylinder length="0.05" radius="0.02"/>
      </geometry>
    </collision>
    <inertial>
      <mass value="0.2"/>
      <inertia ixx="0.03" ixy="0" ixz="0" iyy="0.03" iyz="0" izz="0.03"/>
    </inertial>
  </link>
  <joint name="motor_arm_m3" type="revolute">
    <origin rpy="0 0 0" xyz="0.1 0 0"/>
    <parent link="arm_section_1_ext"/>
    <child link="arm_section_2"/>
    <limit effort="100.0" lower="-1.57" upper="1.57" velocity="0.5"/>
    <axis xyz="0 0 -1"/>
  </joint>
  <link name="arm_section_3">
    <visual>
      <origin rpy="0 3.14159268 0" xyz="0 0 0"/>
      <geometry>
        <mesh filename="meshes/section_3.obj"/>
      </geometry>
      <material name="black"/>
    </visual>
    <collision>
      <origin rpy="1.5707963267949 0 0" xyz="0 -0.025 0"/>
      <geometry>
        <cylinder length="0.05" radius="0.02"/>
      </geometry>
    </collision>
    <inertial>
      <mass value="0.2"/>
      <inertia ixx="0.03" ixy="0" ixz="0" iyy="0.03" iyz="0" izz="0.03"/>
    </inertial>
  </link>
  <joint name="motor_arm_m4" type="revolute">
    <origin rpy="0 -1.5707963267949 0" xyz="0.045 0 0"/>
    <parent link="arm_section_2"/>
    <child link="arm_section_3"/>
    <limit effort="100.0" lower="-3.14" upper="3.14" velocity="0.5"/>
    <axis xyz="0 0 -1"/>
  </joint>
  <link name="arm_section_4">
    <visual>
      <origin rpy="0 0 0" xyz="0 0 0"/>
      <geometry>
        <mesh filename="meshes/section_1.obj"/>
      </geometry>
      <material name="black"/>
    </visual>
    <collision>
      <origin rpy="0 0 0" xyz="0.025 0 0"/>
      <geometry>
        <cylinder length="0.05" radius="0.02"/>
      </geometry>
    </collision>
    <inertial>
      <mass value="0.2"/>
      <inertia ixx="0.03" ixy="0" ixz="0" iyy="0.03" iyz="0" izz="0.03"/>
    </inertial>
  </link>
  <joint name="motor_arm_m5" type="revolute">
    <origin rpy="-1.57 0 3.14" xyz="0 -0.048 0"/>
    <parent link="arm_section_3"/>
    <child link="arm_section_4"/>
    <limit effort="100.0" lower="-1.57" upper="1.57" velocity="0.5"/>
    <axis xyz="1 0 0"/>
  </joint>
  <link name="arm_section_4_ext">
    <visual>
      <origin rpy="0 0 0" xyz="0 0 0"/>
      <geometry>
        <mesh filename="meshes/section_2.obj"/>
      </geometry>
      <material name="black"/>
    </visual>
    <collision>
      <origin rpy="0 1.5707963267949 0" xyz="0.025 0 0"/>
      <geometry>
        <cylinder length="0.05" radius="0.02"/>
      </geometry>
    </collision>
    <inertial>
      <mass value="0.2"/>
      <inertia ixx="0.03" ixy="0" ixz="0" iyy="0.03" iyz="0" izz="0.03"/>
    </inertial>
  </link>
  <joint name="motor_arm_m6" type="revolute">
    <origin rpy="0 0 0" xyz="0 0 0.05"/>
    <parent link="arm_section_4"/>
    <child link="arm_section_4_ext"/>
    <limit effort="100.0" lower="-1.57" upper="1.57" velocity="0.5"/>
    <axis xyz="1 0 0"/>
  </joint>

  <!-- Sensors and Tools -->
  <link name="turret_plate">
    <visual>
      <origin rpy="0 0 0" xyz="0 0 0"/>
      <geometry>
        <mesh filename="stl/arm_turret_gdrt_fcs.stl" scale= "0.003 0.003 0.003"/>
      </geometry>
      <material name="grey"/>
    </visual>
  </link>
  <joint name="turret_plate_base" type="fixed">
    <origin rpy="-3.14 0 0" xyz="0 -0.02 -0.015"/>
    <parent link="arm_section_4_ext"/>
    <child link="turret_plate"/>
    <limit effort="100.0" lower="-1.57" upper="1.57" velocity="0.5"/>
    <axis xyz="0 0 1"/>
  </joint>

  <link name="turret_drill">
    <visual>
      <origin rpy="0 0 0" xyz="0 0 0"/>
      <geometry>
        <mesh filename="stl/arm_turret_drill.stl" scale= "0.002 0.002 0.002"/>
      </geometry>
      <material name="black"/>
    </visual>
  </link>
  <joint name="turret_drill_base" type="fixed">
    <origin rpy="-1.57 0 0" xyz="0 -0.02 -0.05"/>
    <parent link="turret_plate"/>
    <child link="turret_drill"/>
    <axis xyz="0 0 1"/>
  </joint>
  <link name="turret_pixl">
    <visual>
      <origin rpy="0 0 0" xyz="0 0 0"/>
      <geometry>
        <mesh filename="stl/arm_turret_pixl.stl" scale= "0.0015 0.0015 0.0015"/>
      </geometry>
      <material name="grey"/>
    </visual>
  </link>
  <joint name="turret_pixl_base" type="fixed">
    <origin rpy="0 0 1.57" xyz="-0.03 0.075 0.02"/>
    <parent link="turret_drill"/>
    <child link="turret_pixl"/>
    <axis xyz="0 0 1"/>
  </joint>
  <link name="turret_shwa">
    <visual>
      <origin rpy="0 0 0" xyz="0 0 0"/>
      <geometry>
        <mesh filename="stl/arm_turret_sherloc_watson.stl" scale= "0.002 0.002 0.002"/>
      </geometry>
      <material name="grey"/>
    </visual>
  </link>
  <joint name="turret_shwa_base" type="fixed">
    <origin rpy="0 0 0" xyz="0 0.03 0"/>
    <parent link="turret_drill"/>
    <child link="turret_shwa"/>
    <axis xyz="0 0 1"/>
  </joint>

  <!-- High Gain Antenna -->
  <link name="hga_base_link">
    <visual>
      <geometry>
        <mesh filename="stl/hga_base.stl" scale="0.001 0.001 0.001"/>
      </geometry>
    <material name="black"/>
    <origin rpy="-1.57 0 0" xyz="0 0 0"/>
    </visual>
  </link>
  <joint name="hga_base_base" type="fixed">
    <parent link="chassis_front_link"/>
    <child link="hga_base_link"/>
    <origin rpy="0 0 0" xyz="0.1303 0.0266 0.043"/>
  </joint>

  <link name="hga_pin_link">
    <visual>
      <geometry>
        <mesh filename="stl/hga_azimuth_pin.stl" scale="0.001 0.001 0.001"/>
      </geometry>
    <origin rpy="1.57 0 0" xyz="0 0 0"/>
    <material name="black"/>
    </visual>
  </link>
  <joint name="pin_base" type="fixed">
    <parent link="hga_base_link"/>
    <child link="hga_pin_link"/>
    <axis xyz="0 0 1"/>
    <origin rpy="0 0 0" xyz="0 -0.0015 -0.01"/>
    <limit effort="100.0" lower="-3.14" upper="3.14" velocity="0.7"/>
  </joint>

  <link name="hga_antenna_link">
    <visual>
      <geometry>
        <mesh filename="stl/hga_antenna.stl" scale="0.001 0.001 0.001"/>
      </geometry>
      <origin rpy="0 0 3.14" xyz="0 0 0"/>
      <material name="orange"/>
    </visual>
  </link>
  <joint name="antenna_pin" type="fixed">
    <parent link="hga_pin_link"/>
    <child link="hga_antenna_link"/>
    <axis xyz="0 1 0"/>
    <origin rpy="0 0 0" xyz="0.0019 -0.001 0.021"/>
    <limit effort="100.0" lower="-3.14" upper="3.14" velocity="0.7"/>
  </joint>

  <!-- Mastercams -->
  <link name="mastercam_rear_link">
    <visual>
      <geometry>
        <mesh filename="stl/mastcam_z.stl" scale="0.0009 0.0009 0.0009"/>
      </geometry>
    <origin rpy="0 1.57 0" xyz="0 0 0"/>
    <material name="grey"/>
    </visual>
  </link>
    <joint name="mastercam_rear_base" type="fixed">
    <parent link="chassis_front_link"/>
    <child link="mastercam_rear_link"/>
    <origin rpy="3.14 0.1 0" xyz="0.078 -0.02 0.02"/>
  </joint>

  <link name="mastercam2_rear_link">
    <visual>
      <geometry>
        <mesh filename="stl/mastcam_z.stl" scale="0.0009 0.0009 0.0009"/>
      </geometry>
    <origin rpy="0 1.57 0" xyz="0 0 0"/>
    <material name="grey"/>
    </visual>
  </link>
    <joint name="mastercam2_rear_base" type="fixed">
    <parent link="chassis_front_link"/>
    <child link="mastercam2_rear_link"/>
    <origin rpy="3.14 0.1 0" xyz="0.078 0.018 0.02"/>
  </joint>

  <link name="mastercam_front1_link">
    <visual>
      <geometry>
        <mesh filename="stl/mastcam_z.stl" scale="0.00085 0.00085 0.00085"/>
      </geometry>
    <origin rpy="0 1.57 3.14" xyz="0 0 0"/>
    <material name="grey"/>
    </visual>
  </link>
  <joint name="mastercam_front1_base" type="fixed">
    <parent link="chassis_front_link"/>
    <child link="mastercam_front1_link"/>
    <origin rpy="0 0 0" xyz="-0.09 0 -0.03"/>
  </joint>
</robot>
